Workbook
Name PersonList: Lists!$A$2:$A$6
Name ShowList: Lists!$C$2:$C$10
Name CauseList: Lists!$E$2:$E$13

Sheet Overview
B1: Programme update
B2: SAMPLE-FITOUT · data date 30 Jun 2024 · Whole programme
B3: =IF(INFO("RECALC")="Automatic","","If these figures are struck through, or do not follow what is typed, Excel is calculating manually: press F9 to update them, or turn it on for good with Formulas › Calculation Options › Automatic.") -> If these figures are struck through, or do not follow what is typed, Excel is calculating manually: press F9 to update them, or turn it on for good with Formulas › Calculation Options › Automatic.
C4: PERSON ▾ | E4: SHOW ▾ | G4: FIND
C5: Everyone | E5: All activities | K5: Pick from the arrows - the figures and the lists below follow.
C7: ACTIVITIES | E7: UPDATED | F7: NEED ATTENTION | H7: FINISHING LATE | K7: CRITICAL | N7: COMPLETE | Q7: UPDATES IN
C8: =SUM(Data!$T$2:$T$61) -> 60 | E8: =SUMIFS(Data!$R$2:$R$61,Data!$T$2:$T$61,1) -> 0 | F8: =COUNTIFS(Data!$T$2:$T$61,1,Data!$P$2:$P$61,"Reason needed")+COUNTIFS(Data!$T$2:$T$61,1,Data!$P$2:$P$61,"Start date needed")+COUNTIFS(Data!$T$2:$T$61,1,Data!$P$2:$P$61,"Finish date needed")+COUNTIFS(Data!$T$2:$T$61,1,Data!$P$2:$P$61,"Date in the future") -> 3 | H8: =COUNTIFS(Data!$T$2:$T$61,1,Data!$O$2:$O$61,">0",Data!$L$2:$L$61,"") -> 0 | K8: =COUNTIFS(Data!$T$2:$T$61,1,Data!$S$2:$S$61,"Yes",Data!$L$2:$L$61,"") -> 15 | N8: =COUNTIFS(Data!$T$2:$T$61,1,Data!$L$2:$L$61,">0") -> 33 | Q8: =IFERROR(SUMIFS(Data!$R$2:$R$61,Data!$T$2:$T$61,1)/SUM(Data!$T$2:$T$61),0) -> 0
C9: ="Whole programme" -> Whole programme | E9: ="of "&SUM(Data!$T$2:$T$61)&" have an entry" -> of 60 have an entry | F9: ="a cause, a date or a check missing" -> a cause, a date or a check missing | H9: ="not finished, past the planned finish" -> not finished, past the planned finish | K9: ="not finished" -> not finished | N9: ="actual finish entered" -> actual finish entered | Q9: ="of the activities chosen" -> of the activities chosen
B12: Updates by person | E12: Click a name to open their sheet
C13: Responsible Person | D13: Activities | E13: Updates in | F13: Need attention | G13: Late | H13: Critical | I13: Complete | J13: Return | S13: Updated | T13: Not yet
C14: =HYPERLINK("#'Dan Lowe'!G10","Dan Lowe - Design Lead") -> Dan Lowe - Design Lead | D14: =COUNTIFS(Data!$A$2:$A$61,"=Dan Lowe - Design Lead") -> 19 | E14: =IFERROR(S14/D14,0) -> 0 | F14: =COUNTIFS(Data!$A$2:$A$61,"=Dan Lowe - Design Lead",Data!$P$2:$P$61,"Reason needed")+COUNTIFS(Data!$A$2:$A$61,"=Dan Lowe - Design Lead",Data!$P$2:$P$61,"Start date needed")+COUNTIFS(Data!$A$2:$A$61,"=Dan Lowe - Design Lead",Data!$P$2:$P$61,"Finish date needed")+COUNTIFS(Data!$A$2:$A$61,"=Dan Lowe - Design Lead",Data!$P$2:$P$61,"Date in the future") -> 0 | G14: =COUNTIFS(Data!$A$2:$A$61,"=Dan Lowe - Design Lead",Data!$O$2:$O$61,">0",Data!$L$2:$L$61,"") -> 0 | H14: =COUNTIFS(Data!$A$2:$A$61,"=Dan Lowe - Design Lead",Data!$S$2:$S$61,"Yes",Data!$L$2:$L$61,"") -> 0 | I14: =COUNTIFS(Data!$A$2:$A$61,"=Dan Lowe - Design Lead",Data!$L$2:$L$61,">0") -> 19 | J14: =IF(D14=0,"",IF(S14>=D14,"✓ All in",IF(S14>0,S14&" of "&D14,"Waiting"))) -> Waiting | S14: =SUMIFS(Data!$R$2:$R$61,Data!$A$2:$A$61,"=Dan Lowe - Design Lead") -> 0 | T14: =D14-S14 -> 19
C15: =HYPERLINK("#'Priya Menon'!G10","Priya Menon - Project Manager") -> Priya Menon - Project Manager | D15: =COUNTIFS(Data!$A$2:$A$61,"=Priya Menon - Project Manager") -> 2 | E15: =IFERROR(S15/D15,0) -> 0 | F15: =COUNTIFS(Data!$A$2:$A$61,"=Priya Menon - Project Manager",Data!$P$2:$P$61,"Reason needed")+COUNTIFS(Data!$A$2:$A$61,"=Priya Menon - Project Manager",Data!$P$2:$P$61,"Start date needed")+COUNTIFS(Data!$A$2:$A$61,"=Priya Menon - Project Manager",Data!$P$2:$P$61,"Finish date needed")+COUNTIFS(Data!$A$2:$A$61,"=Priya Menon - Project Manager",Data!$P$2:$P$61,"Date in the future") -> 0 | G15: =COUNTIFS(Data!$A$2:$A$61,"=Priya Menon - Project Manager",Data!$O$2:$O$61,">0",Data!$L$2:$L$61,"") -> 0 | H15: =COUNTIFS(Data!$A$2:$A$61,"=Priya Menon - Project Manager",Data!$S$2:$S$61,"Yes",Data!$L$2:$L$61,"") -> 0 | I15: =COUNTIFS(Data!$A$2:$A$61,"=Priya Menon - Project Manager",Data!$L$2:$L$61,">0") -> 1 | J15: =IF(D15=0,"",IF(S15>=D15,"✓ All in",IF(S15>0,S15&" of "&D15,"Waiting"))) -> Waiting | S15: =SUMIFS(Data!$R$2:$R$61,Data!$A$2:$A$61,"=Priya Menon - Project Manager") -> 0 | T15: =D15-S15 -> 2
C16: =HYPERLINK("#'Sara Moss'!G10","Sara Moss - Site Manager") -> Sara Moss - Site Manager | D16: =COUNTIFS(Data!$A$2:$A$61,"=Sara Moss - Site Manager") -> 20 | E16: =IFERROR(S16/D16,0) -> 0 | F16: =COUNTIFS(Data!$A$2:$A$61,"=Sara Moss - Site Manager",Data!$P$2:$P$61,"Reason needed")+COUNTIFS(Data!$A$2:$A$61,"=Sara Moss - Site Manager",Data!$P$2:$P$61,"Start date needed")+COUNTIFS(Data!$A$2:$A$61,"=Sara Moss - Site Manager",Data!$P$2:$P$61,"Finish date needed")+COUNTIFS(Data!$A$2:$A$61,"=Sara Moss - Site Manager",Data!$P$2:$P$61,"Date in the future") -> 2 | G16: =COUNTIFS(Data!$A$2:$A$61,"=Sara Moss - Site Manager",Data!$O$2:$O$61,">0",Data!$L$2:$L$61,"") -> 0 | H16: =COUNTIFS(Data!$A$2:$A$61,"=Sara Moss - Site Manager",Data!$S$2:$S$61,"Yes",Data!$L$2:$L$61,"") -> 7 | I16: =COUNTIFS(Data!$A$2:$A$61,"=Sara Moss - Site Manager",Data!$L$2:$L$61,">0") -> 6 | J16: =IF(D16=0,"",IF(S16>=D16,"✓ All in",IF(S16>0,S16&" of "&D16,"Waiting"))) -> Waiting | S16: =SUMIFS(Data!$R$2:$R$61,Data!$A$2:$A$61,"=Sara Moss - Site Manager") -> 0 | T16: =D16-S16 -> 20
C17: =HYPERLINK("#'Tom Reid'!G10","Tom Reid - Package Manager") -> Tom Reid - Package Manager | D17: =COUNTIFS(Data!$A$2:$A$61,"=Tom Reid - Package Manager") -> 19 | E17: =IFERROR(S17/D17,0) -> 0 | F17: =COUNTIFS(Data!$A$2:$A$61,"=Tom Reid - Package Manager",Data!$P$2:$P$61,"Reason needed")+COUNTIFS(Data!$A$2:$A$61,"=Tom Reid - Package Manager",Data!$P$2:$P$61,"Start date needed")+COUNTIFS(Data!$A$2:$A$61,"=Tom Reid - Package Manager",Data!$P$2:$P$61,"Finish date needed")+COUNTIFS(Data!$A$2:$A$61,"=Tom Reid - Package Manager",Data!$P$2:$P$61,"Date in the future") -> 1 | G17: =COUNTIFS(Data!$A$2:$A$61,"=Tom Reid - Package Manager",Data!$O$2:$O$61,">0",Data!$L$2:$L$61,"") -> 0 | H17: =COUNTIFS(Data!$A$2:$A$61,"=Tom Reid - Package Manager",Data!$S$2:$S$61,"Yes",Data!$L$2:$L$61,"") -> 8 | I17: =COUNTIFS(Data!$A$2:$A$61,"=Tom Reid - Package Manager",Data!$L$2:$L$61,">0") -> 7 | J17: =IF(D17=0,"",IF(S17>=D17,"✓ All in",IF(S17>0,S17&" of "&D17,"Waiting"))) -> Waiting | S17: =SUMIFS(Data!$R$2:$R$61,Data!$A$2:$A$61,"=Tom Reid - Package Manager") -> 0 | T17: =D17-S17 -> 19
C18: Everyone | D18: =SUM(D14:D17) -> 60 | E18: =IFERROR(S18/D18,0) -> 0 | F18: =SUM(F14:F17) -> 3 | G18: =SUM(G14:G17) -> 0 | H18: =SUM(H14:H17) -> 15 | I18: =SUM(I14:I17) -> 33 | J18: =S18&" of "&D18 -> 0 of 60 | S18: =SUM(S14:S17) -> 0
B25: ="Activities · "&IF(Overview!$C$5="Everyone","everyone",Overview!$C$5)&" · "&LOWER(Overview!$E$5)&IF(Overview!$G$5<>""," · matching """&Overview!$G$5&"""","") -> Activities · everyone · all activities | R25: ="Showing "&Data!$V$61&" of 60" -> Showing 60 of 60
C27: Person | D27: Activity ID | E27: Activity name | F27: WBS | G27: Status | H27: Start | I27: Finish | J27: Physical % | K27: Actual start | L27: Actual finish | M27: Actual % | N27: Expected finish | O27: Days late | P27: Check | Q27: Delay cause | R27: Notes
B28: =IF($T28="","",HYPERLINK("#'"&INDEX(Data!$B$2:$B$61,$T28)&"'!G"&INDEX(Data!$C$2:$C$61,$T28),"✎")) -> ✎ | C28: =IF($T28="","",INDEX(Data!$A$2:$A$61,$T28)) -> Dan Lowe - Design Lead | D28: =IF($T28="","",INDEX(Data!$D$2:$D$61,$T28)) -> A1010 | E28: =IF($T28="","Nothing matches - choose Everyone and All activities, or clear Find.",INDEX(Data!$E$2:$E$61,$T28)) -> Design package 01 | F28: =IF($T28="","",INDEX(Data!$F$2:$F$61,$T28)) -> Engineering | G28: =IF($T28="","",INDEX(Data!$G$2:$G$61,$T28)) -> Completed | H28: =IF($T28="","",INDEX(Data!$H$2:$H$61,$T28)) -> 45296 | I28: =IF($T28="","",INDEX(Data!$I$2:$I$61,$T28)) -> 45307 | J28: =IF($T28="","",INDEX(Data!$J$2:$J$61,$T28)) -> 100 | K28: =IF($T28="","",INDEX(Data!$K$2:$K$61,$T28)) -> 45296 | L28: =IF($T28="","",INDEX(Data!$L$2:$L$61,$T28)) -> 45307 | M28: =IF($T28="","",INDEX(Data!$M$2:$M$61,$T28)) | N28: =IF($T28="","",INDEX(Data!$N$2:$N$61,$T28)) | O28: =IF($T28="","",INDEX(Data!$O$2:$O$61,$T28)) -> 0 | P28: =IF($T28="","",INDEX(Data!$P$2:$P$61,$T28)) -> ✓ Complete | Q28: =IF($T28="","",INDEX(Data!$W$2:$W$61,$T28)) | R28: =IF($T28="","",INDEX(Data!$Q$2:$Q$61,$T28)) | S28: =IF($T28="","",INDEX(Data!$R$2:$R$61,$T28)) -> 0 | T28: =IFERROR(MATCH(1,Data!$V$2:$V$61,0),"") -> 1
B29: =IF($T29="","",HYPERLINK("#'"&INDEX(Data!$B$2:$B$61,$T29)&"'!G"&INDEX(Data!$C$2:$C$61,$T29),"✎")) -> ✎ | C29: =IF($T29="","",INDEX(Data!$A$2:$A$61,$T29)) -> Dan Lowe - Design Lead | D29: =IF($T29="","",INDEX(Data!$D$2:$D$61,$T29)) -> A1020 | E29: =IF($T29="","",INDEX(Data!$E$2:$E$61,$T29)) -> Design package 02 | F29: =IF($T29="","",INDEX(Data!$F$2:$F$61,$T29)) -> Engineering | G29: =IF($T29="","",INDEX(Data!$G$2:$G$61,$T29)) -> Completed | H29: =IF($T29="","",INDEX(Data!$H$2:$H$61,$T29)) -> 45301 | I29: =IF($T29="","",INDEX(Data!$I$2:$I$61,$T29)) -> 45304 | J29: =IF($T29="","",INDEX(Data!$J$2:$J$61,$T29)) -> 100 | K29: =IF($T29="","",INDEX(Data!$K$2:$K$61,$T29)) -> 45301 | L29: =IF($T29="","",INDEX(Data!$L$2:$L$61,$T29)) -> 45304 | M29: =IF($T29="","",INDEX(Data!$M$2:$M$61,$T29)) | N29: =IF($T29="","",INDEX(Data!$N$2:$N$61,$T29)) | O29: =IF($T29="","",INDEX(Data!$O$2:$O$61,$T29)) -> 0 | P29: =IF($T29="","",INDEX(Data!$P$2:$P$61,$T29)) -> ✓ Complete | Q29: =IF($T29="","",INDEX(Data!$W$2:$W$61,$T29)) | R29: =IF($T29="","",INDEX(Data!$Q$2:$Q$61,$T29)) | S29: =IF($T29="","",INDEX(Data!$R$2:$R$61,$T29)) -> 0 | T29: =IFERROR(MATCH(2,Data!$V$2:$V$61,0),"") -> 2
B30: =IF($T30="","",HYPERLINK("#'"&INDEX(Data!$B$2:$B$61,$T30)&"'!G"&INDEX(Data!$C$2:$C$61,$T30),"✎")) -> ✎ | C30: =IF($T30="","",INDEX(Data!$A$2:$A$61,$T30)) -> Dan Lowe - Design Lead | D30: =IF($T30="","",INDEX(Data!$D$2:$D$61,$T30)) -> A1030 | E30: =IF($T30="","",INDEX(Data!$E$2:$E$61,$T30)) -> Design package 03 | F30: =IF($T30="","",INDEX(Data!$F$2:$F$61,$T30)) -> Engineering | G30: =IF($T30="","",INDEX(Data!$G$2:$G$61,$T30)) -> Completed | H30: =IF($T30="","",INDEX(Data!$H$2:$H$61,$T30)) -> 45302 | I30: =IF($T30="","",INDEX(Data!$I$2:$I$61,$T30)) -> 45309 | J30: =IF($T30="","",INDEX(Data!$J$2:$J$61,$T30)) -> 100 | K30: =IF($T30="","",INDEX(Data!$K$2:$K$61,$T30)) -> 45302 | L30: =IF($T30="","",INDEX(Data!$L$2:$L$61,$T30)) -> 45309 | M30: =IF($T30="","",INDEX(Data!$M$2:$M$61,$T30)) | N30: =IF($T30="","",INDEX(Data!$N$2:$N$61,$T30)) | O30: =IF($T30="","",INDEX(Data!$O$2:$O$61,$T30)) -> 0 | P30: =IF($T30="","",INDEX(Data!$P$2:$P$61,$T30)) -> ✓ Complete | Q30: =IF($T30="","",INDEX(Data!$W$2:$W$61,$T30)) | R30: =IF($T30="","",INDEX(Data!$Q$2:$Q$61,$T30)) | S30: =IF($T30="","",INDEX(Data!$R$2:$R$61,$T30)) -> 0 | T30: =IFERROR(MATCH(3,Data!$V$2:$V$61,0),"") -> 3
B31: =IF($T31="","",HYPERLINK("#'"&INDEX(Data!$B$2:$B$61,$T31)&"'!G"&INDEX(Data!$C$2:$C$61,$T31),"✎")) -> ✎ | C31: =IF($T31="","",INDEX(Data!$A$2:$A$61,$T31)) -> Dan Lowe - Design Lead | D31: =IF($T31="","",INDEX(Data!$D$2:$D$61,$T31)) -> A1040 | E31: =IF($T31="","",INDEX(Data!$E$2:$E$61,$T31)) -> Design package 04 | F31: =IF($T31="","",INDEX(Data!$F$2:$F$61,$T31)) -> Engineering | G31: =IF($T31="","",INDEX(Data!$G$2:$G$61,$T31)) -> Completed | H31: =IF($T31="","",INDEX(Data!$H$2:$H$61,$T31)) -> 45305 | I31: =IF($T31="","",INDEX(Data!$I$2:$I$61,$T31)) -> 45319 | J31: =IF($T31="","",INDEX(Data!$J$2:$J$61,$T31)) -> 100 | K31: =IF($T31="","",INDEX(Data!$K$2:$K$61,$T31)) -> 45305 | L31: =IF($T31="","",INDEX(Data!$L$2:$L$61,$T31)) -> 45319 | M31: =IF($T31="","",INDEX(Data!$M$2:$M$61,$T31)) | N31: =IF($T31="","",INDEX(Data!$N$2:$N$61,$T31)) | O31: =IF($T31="","",INDEX(Data!$O$2:$O$61,$T31)) -> 0 | P31: =IF($T31="","",INDEX(Data!$P$2:$P$61,$T31)) -> ✓ Complete | Q31: =IF($T31="","",INDEX(Data!$W$2:$W$61,$T31)) | R31: =IF($T31="","",INDEX(Data!$Q$2:$Q$61,$T31)) | S31: =IF($T31="","",INDEX(Data!$R$2:$R$61,$T31)) -> 0 | T31: =IFERROR(MATCH(4,Data!$V$2:$V$61,0),"") -> 4
B32: =IF($T32="","",HYPERLINK("#'"&INDEX(Data!$B$2:$B$61,$T32)&"'!G"&INDEX(Data!$C$2:$C$61,$T32),"✎")) -> ✎ | C32: =IF($T32="","",INDEX(Data!$A$2:$A$61,$T32)) -> Dan Lowe - Design Lead | D32: =IF($T32="","",INDEX(Data!$D$2:$D$61,$T32)) -> A1050 | E32: =IF($T32="","",INDEX(Data!$E$2:$E$61,$T32)) -> Design package 05 | F32: =IF($T32="","",INDEX(Data!$F$2:$F$61,$T32)) -> Engineering | G32: =IF($T32="","",INDEX(Data!$G$2:$G$61,$T32)) -> Completed | H32: =IF($T32="","",INDEX(Data!$H$2:$H$61,$T32)) -> 45312 | I32: =IF($T32="","",INDEX(Data!$I$2:$I$61,$T32)) -> 45315 | J32: =IF($T32="","",INDEX(Data!$J$2:$J$61,$T32)) -> 100 | K32: =IF($T32="","",INDEX(Data!$K$2:$K$61,$T32)) -> 45312 | L32: =IF($T32="","",INDEX(Data!$L$2:$L$61,$T32)) -> 45315 | M32: =IF($T32="","",INDEX(Data!$M$2:$M$61,$T32)) | N32: =IF($T32="","",INDEX(Data!$N$2:$N$61,$T32)) | O32: =IF($T32="","",INDEX(Data!$O$2:$O$61,$T32)) -> 0 | P32: =IF($T32="","",INDEX(Data!$P$2:$P$61,$T32)) -> ✓ Complete | Q32: =IF($T32="","",INDEX(Data!$W$2:$W$61,$T32)) | R32: =IF($T32="","",INDEX(Data!$Q$2:$Q$61,$T32)) | S32: =IF($T32="","",INDEX(Data!$R$2:$R$61,$T32)) -> 0 | T32: =IFERROR(MATCH(5,Data!$V$2:$V$61,0),"") -> 5
B33: =IF($T33="","",HYPERLINK("#'"&INDEX(Data!$B$2:$B$61,$T33)&"'!G"&INDEX(Data!$C$2:$C$61,$T33),"✎")) -> ✎ | C33: =IF($T33="","",INDEX(Data!$A$2:$A$61,$T33)) -> Dan Lowe - Design Lead | D33: =IF($T33="","",INDEX(Data!$D$2:$D$61,$T33)) -> A1060 | E33: =IF($T33="","",INDEX(Data!$E$2:$E$61,$T33)) -> Design package 06 | F33: =IF($T33="","",INDEX(Data!$F$2:$F$61,$T33)) -> Engineering | G33: =IF($T33="","",INDEX(Data!$G$2:$G$61,$T33)) -> Completed | H33: =IF($T33="","",INDEX(Data!$H$2:$H$61,$T33)) -> 45313 | I33: =IF($T33="","",INDEX(Data!$I$2:$I$61,$T33)) -> 45324 | J33: =IF($T33="","",INDEX(Data!$J$2:$J$61,$T33)) -> 100 | K33: =IF($T33="","",INDEX(Data!$K$2:$K$61,$T33)) -> 45313 | L33: =IF($T33="","",INDEX(Data!$L$2:$L$61,$T33)) -> 45324 | M33: =IF($T33="","",INDEX(Data!$M$2:$M$61,$T33)) | N33: =IF($T33="","",INDEX(Data!$N$2:$N$61,$T33)) | O33: =IF($T33="","",INDEX(Data!$O$2:$O$61,$T33)) -> 0 | P33: =IF($T33="","",INDEX(Data!$P$2:$P$61,$T33)) -> ✓ Complete | Q33: =IF($T33="","",INDEX(Data!$W$2:$W$61,$T33)) | R33: =IF($T33="","",INDEX(Data!$Q$2:$Q$61,$T33)) | S33: =IF($T33="","",INDEX(Data!$R$2:$R$61,$T33)) -> 0 | T33: =IFERROR(MATCH(6,Data!$V$2:$V$61,0),"") -> 6
B34: =IF($T34="","",HYPERLINK("#'"&INDEX(Data!$B$2:$B$61,$T34)&"'!G"&INDEX(Data!$C$2:$C$61,$T34),"✎")) -> ✎ | C34: =IF($T34="","",INDEX(Data!$A$2:$A$61,$T34)) -> Dan Lowe - Design Lead | D34: =IF($T34="","",INDEX(Data!$D$2:$D$61,$T34)) -> A1070 | E34: =IF($T34="","",INDEX(Data!$E$2:$E$61,$T34)) -> Design package 07 | F34: =IF($T34="","",INDEX(Data!$F$2:$F$61,$T34)) -> Engineering | G34: =IF($T34="","",INDEX(Data!$G$2:$G$61,$T34)) -> Completed | H34: =IF($T34="","",INDEX(Data!$H$2:$H$61,$T34)) -> 45318 | I34: =IF($T34="","",INDEX(Data!$I$2:$I$61,$T34)) -> 45321 | J34: =IF($T34="","",INDEX(Data!$J$2:$J$61,$T34)) -> 100 | K34: =IF($T34="","",INDEX(Data!$K$2:$K$61,$T34)) -> 45318 | L34: =IF($T34="","",INDEX(Data!$L$2:$L$61,$T34)) -> 45321 | M34: =IF($T34="","",INDEX(Data!$M$2:$M$61,$T34)) | N34: =IF($T34="","",INDEX(Data!$N$2:$N$61,$T34)) | O34: =IF($T34="","",INDEX(Data!$O$2:$O$61,$T34)) -> 0 | P34: =IF($T34="","",INDEX(Data!$P$2:$P$61,$T34)) -> ✓ Complete | Q34: =IF($T34="","",INDEX(Data!$W$2:$W$61,$T34)) | R34: =IF($T34="","",INDEX(Data!$Q$2:$Q$61,$T34)) | S34: =IF($T34="","",INDEX(Data!$R$2:$R$61,$T34)) -> 0 | T34: =IFERROR(MATCH(7,Data!$V$2:$V$61,0),"") -> 7
B35: =IF($T35="","",HYPERLINK("#'"&INDEX(Data!$B$2:$B$61,$T35)&"'!G"&INDEX(Data!$C$2:$C$61,$T35),"✎")) -> ✎ | C35: =IF($T35="","",INDEX(Data!$A$2:$A$61,$T35)) -> Dan Lowe - Design Lead | D35: =IF($T35="","",INDEX(Data!$D$2:$D$61,$T35)) -> A1080 | E35: =IF($T35="","",INDEX(Data!$E$2:$E$61,$T35)) -> Design package 08 | F35: =IF($T35="","",INDEX(Data!$F$2:$F$61,$T35)) -> Engineering | G35: =IF($T35="","",INDEX(Data!$G$2:$G$61,$T35)) -> Completed | H35: =IF($T35="","",INDEX(Data!$H$2:$H$61,$T35)) -> 45319 | I35: =IF($T35="","",INDEX(Data!$I$2:$I$61,$T35)) -> 45322 | J35: =IF($T35="","",INDEX(Data!$J$2:$J$61,$T35)) -> 100 | K35: =IF($T35="","",INDEX(Data!$K$2:$K$61,$T35)) -> 45319 | L35: =IF($T35="","",INDEX(Data!$L$2:$L$61,$T35)) -> 45322 | M35: =IF($T35="","",INDEX(Data!$M$2:$M$61,$T35)) | N35: =IF($T35="","",INDEX(Data!$N$2:$N$61,$T35)) | O35: =IF($T35="","",INDEX(Data!$O$2:$O$61,$T35)) -> 0 | P35: =IF($T35="","",INDEX(Data!$P$2:$P$61,$T35)) -> ✓ Complete | Q35: =IF($T35="","",INDEX(Data!$W$2:$W$61,$T35)) | R35: =IF($T35="","",INDEX(Data!$Q$2:$Q$61,$T35)) | S35: =IF($T35="","",INDEX(Data!$R$2:$R$61,$T35)) -> 0 | T35: =IFERROR(MATCH(8,Data!$V$2:$V$61,0),"") -> 8
B36: =IF($T36="","",HYPERLINK("#'"&INDEX(Data!$B$2:$B$61,$T36)&"'!G"&INDEX(Data!$C$2:$C$61,$T36),"✎")) -> ✎ | C36: =IF($T36="","",INDEX(Data!$A$2:$A$61,$T36)) -> Dan Lowe - Design Lead | D36: =IF($T36="","",INDEX(Data!$D$2:$D$61,$T36)) -> A1090 | E36: =IF($T36="","",INDEX(Data!$E$2:$E$61,$T36)) -> Design package 09 | F36: =IF($T36="","",INDEX(Data!$F$2:$F$61,$T36)) -> Engineering | G36: =IF($T36="","",INDEX(Data!$G$2:$G$61,$T36)) -> Completed | H36: =IF($T36="","",INDEX(Data!$H$2:$H$61,$T36)) -> 45320 | I36: =IF($T36="","",INDEX(Data!$I$2:$I$61,$T36)) -> 45323 | J36: =IF($T36="","",INDEX(Data!$J$2:$J$61,$T36)) -> 100 | K36: =IF($T36="","",INDEX(Data!$K$2:$K$61,$T36)) -> 45320 | L36: =IF($T36="","",INDEX(Data!$L$2:$L$61,$T36)) -> 45323 | M36: =IF($T36="","",INDEX(Data!$M$2:$M$61,$T36)) | N36: =IF($T36="","",INDEX(Data!$N$2:$N$61,$T36)) | O36: =IF($T36="","",INDEX(Data!$O$2:$O$61,$T36)) -> 0 | P36: =IF($T36="","",INDEX(Data!$P$2:$P$61,$T36)) -> ✓ Complete | Q36: =IF($T36="","",INDEX(Data!$W$2:$W$61,$T36)) | R36: =IF($T36="","",INDEX(Data!$Q$2:$Q$61,$T36)) | S36: =IF($T36="","",INDEX(Data!$R$2:$R$61,$T36)) -> 0 | T36: =IFERROR(MATCH(9,Data!$V$2:$V$61,0),"") -> 9
B37: =IF($T37="","",HYPERLINK("#'"&INDEX(Data!$B$2:$B$61,$T37)&"'!G"&INDEX(Data!$C$2:$C$61,$T37),"✎")) -> ✎ | C37: =IF($T37="","",INDEX(Data!$A$2:$A$61,$T37)) -> Dan Lowe - Design Lead | D37: =IF($T37="","",INDEX(Data!$D$2:$D$61,$T37)) -> A1100 | E37: =IF($T37="","",INDEX(Data!$E$2:$E$61,$T37)) -> Design package 10 | F37: =IF($T37="","",INDEX(Data!$F$2:$F$61,$T37)) -> Engineering | G37: =IF($T37="","",INDEX(Data!$G$2:$G$61,$T37)) -> Completed | H37: =IF($T37="","",INDEX(Data!$H$2:$H$61,$T37)) -> 45321 | I37: =IF($T37="","",INDEX(Data!$I$2:$I$61,$T37)) -> 45325 | J37: =IF($T37="","",INDEX(Data!$J$2:$J$61,$T37)) -> 100 | K37: =IF($T37="","",INDEX(Data!$K$2:$K$61,$T37)) -> 45321 | L37: =IF($T37="","",INDEX(Data!$L$2:$L$61,$T37)) -> 45325 | M37: =IF($T37="","",INDEX(Data!$M$2:$M$61,$T37)) | N37: =IF($T37="","",INDEX(Data!$N$2:$N$61,$T37)) | O37: =IF($T37="","",INDEX(Data!$O$2:$O$61,$T37)) -> 0 | P37: =IF($T37="","",INDEX(Data!$P$2:$P$61,$T37)) -> ✓ Complete | Q37: =IF($T37="","",INDEX(Data!$W$2:$W$61,$T37)) | R37: =IF($T37="","",INDEX(Data!$Q$2:$Q$61,$T37)) | S37: =IF($T37="","",INDEX(Data!$R$2:$R$61,$T37)) -> 0 | T37: =IFERROR(MATCH(10,Data!$V$2:$V$61,0),"") -> 10
B38: =IF($T38="","",HYPERLINK("#'"&INDEX(Data!$B$2:$B$61,$T38)&"'!G"&INDEX(Data!$C$2:$C$61,$T38),"✎")) -> ✎ | C38: =IF($T38="","",INDEX(Data!$A$2:$A$61,$T38)) -> Dan Lowe - Design Lead | D38: =IF($T38="","",INDEX(Data!$D$2:$D$61,$T38)) -> A1110 | E38: =IF($T38="","",INDEX(Data!$E$2:$E$61,$T38)) -> Design package 11 | F38: =IF($T38="","",INDEX(Data!$F$2:$F$61,$T38)) -> Engineering | G38: =IF($T38="","",INDEX(Data!$G$2:$G$61,$T38)) -> Completed | H38: =IF($T38="","",INDEX(Data!$H$2:$H$61,$T38)) -> 45323 | I38: =IF($T38="","",INDEX(Data!$I$2:$I$61,$T38)) -> 45337 | J38: =IF($T38="","",INDEX(Data!$J$2:$J$61,$T38)) -> 100 | K38: =IF($T38="","",INDEX(Data!$K$2:$K$61,$T38)) -> 45323 | L38: =IF($T38="","",INDEX(Data!$L$2:$L$61,$T38)) -> 45337 | M38: =IF($T38="","",INDEX(Data!$M$2:$M$61,$T38)) | N38: =IF($T38="","",INDEX(Data!$N$2:$N$61,$T38)) | O38: =IF($T38="","",INDEX(Data!$O$2:$O$61,$T38)) -> 0 | P38: =IF($T38="","",INDEX(Data!$P$2:$P$61,$T38)) -> ✓ Complete | Q38: =IF($T38="","",INDEX(Data!$W$2:$W$61,$T38)) | R38: =IF($T38="","",INDEX(Data!$Q$2:$Q$61,$T38)) | S38: =IF($T38="","",INDEX(Data!$R$2:$R$61,$T38)) -> 0 | T38: =IFERROR(MATCH(11,Data!$V$2:$V$61,0),"") -> 11
B39: =IF($T39="","",HYPERLINK("#'"&INDEX(Data!$B$2:$B$61,$T39)&"'!G"&INDEX(Data!$C$2:$C$61,$T39),"✎")) -> ✎ | C39: =IF($T39="","",INDEX(Data!$A$2:$A$61,$T39)) -> Dan Lowe - Design Lead | D39: =IF($T39="","",INDEX(Data!$D$2:$D$61,$T39)) -> A1120 | E39: =IF($T39="","",INDEX(Data!$E$2:$E$61,$T39)) -> Design package 12 | F39: =IF($T39="","",INDEX(Data!$F$2:$F$61,$T39)) -> Engineering | G39: =IF($T39="","",INDEX(Data!$G$2:$G$61,$T39)) -> Completed | H39: =IF($T39="","",INDEX(Data!$H$2:$H$61,$T39)) -> 45330 | I39: =IF($T39="","",INDEX(Data!$I$2:$I$61,$T39)) -> 45333 | J39: =IF($T39="","",INDEX(Data!$J$2:$J$61,$T39)) -> 100 | K39: =IF($T39="","",INDEX(Data!$K$2:$K$61,$T39)) -> 45330 | L39: =IF($T39="","",INDEX(Data!$L$2:$L$61,$T39)) -> 45333 | M39: =IF($T39="","",INDEX(Data!$M$2:$M$61,$T39)) | N39: =IF($T39="","",INDEX(Data!$N$2:$N$61,$T39)) | O39: =IF($T39="","",INDEX(Data!$O$2:$O$61,$T39)) -> 0 | P39: =IF($T39="","",INDEX(Data!$P$2:$P$61,$T39)) -> ✓ Complete | Q39: =IF($T39="","",INDEX(Data!$W$2:$W$61,$T39)) | R39: =IF($T39="","",INDEX(Data!$Q$2:$Q$61,$T39)) | S39: =IF($T39="","",INDEX(Data!$R$2:$R$61,$T39)) -> 0 | T39: =IFERROR(MATCH(12,Data!$V$2:$V$61,0),"") -> 12
B40: =IF($T40="","",HYPERLINK("#'"&INDEX(Data!$B$2:$B$61,$T40)&"'!G"&INDEX(Data!$C$2:$C$61,$T40),"✎")) -> ✎ | C40: =IF($T40="","",INDEX(Data!$A$2:$A$61,$T40)) -> Dan Lowe - Design Lead | D40: =IF($T40="","",INDEX(Data!$D$2:$D$61,$T40)) -> A1130 | E40: =IF($T40="","",INDEX(Data!$E$2:$E$61,$T40)) -> Design package 13 | F40: =IF($T40="","",INDEX(Data!$F$2:$F$61,$T40)) -> Engineering | G40: =IF($T40="","",INDEX(Data!$G$2:$G$61,$T40)) -> Completed | H40: =IF($T40="","",INDEX(Data!$H$2:$H$61,$T40)) -> 45331 | I40: =IF($T40="","",INDEX(Data!$I$2:$I$61,$T40)) -> 45334 | J40: =IF($T40="","",INDEX(Data!$J$2:$J$61,$T40)) -> 100 | K40: =IF($T40="","",INDEX(Data!$K$2:$K$61,$T40)) -> 45331 | L40: =IF($T40="","",INDEX(Data!$L$2:$L$61,$T40)) -> 45334 | M40: =IF($T40="","",INDEX(Data!$M$2:$M$61,$T40)) | N40: =IF($T40="","",INDEX(Data!$N$2:$N$61,$T40)) | O40: =IF($T40="","",INDEX(Data!$O$2:$O$61,$T40)) -> 0 | P40: =IF($T40="","",INDEX(Data!$P$2:$P$61,$T40)) -> ✓ Complete | Q40: =IF($T40="","",INDEX(Data!$W$2:$W$61,$T40)) | R40: =IF($T40="","",INDEX(Data!$Q$2:$Q$61,$T40)) | S40: =IF($T40="","",INDEX(Data!$R$2:$R$61,$T40)) -> 0 | T40: =IFERROR(MATCH(13,Data!$V$2:$V$61,0),"") -> 13
B41: =IF($T41="","",HYPERLINK("#'"&INDEX(Data!$B$2:$B$61,$T41)&"'!G"&INDEX(Data!$C$2:$C$61,$T41),"✎")) -> ✎ | C41: =IF($T41="","",INDEX(Data!$A$2:$A$61,$T41)) -> Dan Lowe - Design Lead | D41: =IF($T41="","",INDEX(Data!$D$2:$D$61,$T41)) -> A1140 | E41: =IF($T41="","",INDEX(Data!$E$2:$E$61,$T41)) -> Design package 14 | F41: =IF($T41="","",INDEX(Data!$F$2:$F$61,$T41)) -> Engineering | G41: =IF($T41="","",INDEX(Data!$G$2:$G$61,$T41)) -> Completed | H41: =IF($T41="","",INDEX(Data!$H$2:$H$61,$T41)) -> 45332 | I41: =IF($T41="","",INDEX(Data!$I$2:$I$61,$T41)) -> 45339 | J41: =IF($T41="","",INDEX(Data!$J$2:$J$61,$T41)) -> 100 | K41: =IF($T41="","",INDEX(Data!$K$2:$K$61,$T41)) -> 45332 | L41: =IF($T41="","",INDEX(Data!$L$2:$L$61,$T41)) -> 45339 | M41: =IF($T41="","",INDEX(Data!$M$2:$M$61,$T41)) | N41: =IF($T41="","",INDEX(Data!$N$2:$N$61,$T41)) | O41: =IF($T41="","",INDEX(Data!$O$2:$O$61,$T41)) -> 0 | P41: =IF($T41="","",INDEX(Data!$P$2:$P$61,$T41)) -> ✓ Complete | Q41: =IF($T41="","",INDEX(Data!$W$2:$W$61,$T41)) | R41: =IF($T41="","",INDEX(Data!$Q$2:$Q$61,$T41)) | S41: =IF($T41="","",INDEX(Data!$R$2:$R$61,$T41)) -> 0 | T41: =IFERROR(MATCH(14,Data!$V$2:$V$61,0),"") -> 14
B42: =IF($T42="","",HYPERLINK("#'"&INDEX(Data!$B$2:$B$61,$T42)&"'!G"&INDEX(Data!$C$2:$C$61,$T42),"✎")) -> ✎ | C42: =IF($T42="","",INDEX(Data!$A$2:$A$61,$T42)) -> Dan Lowe - Design Lead | D42: =IF($T42="","",INDEX(Data!$D$2:$D$61,$T42)) -> A1150 | E42: =IF($T42="","",INDEX(Data!$E$2:$E$61,$T42)) -> Design package 15 | F42: =IF($T42="","",INDEX(Data!$F$2:$F$61,$T42)) -> Engineering | G42: =IF($T42="","",INDEX(Data!$G$2:$G$61,$T42)) -> Completed | H42: =IF($T42="","",INDEX(Data!$H$2:$H$61,$T42)) -> 45335 | I42: =IF($T42="","",INDEX(Data!$I$2:$I$61,$T42)) -> 45339 | J42: =IF($T42="","",INDEX(Data!$J$2:$J$61,$T42)) -> 100 | K42: =IF($T42="","",INDEX(Data!$K$2:$K$61,$T42)) -> 45335 | L42: =IF($T42="","",INDEX(Data!$L$2:$L$61,$T42)) -> 45339 | M42: =IF($T42="","",INDEX(Data!$M$2:$M$61,$T42)) | N42: =IF($T42="","",INDEX(Data!$N$2:$N$61,$T42)) | O42: =IF($T42="","",INDEX(Data!$O$2:$O$61,$T42)) -> 0 | P42: =IF($T42="","",INDEX(Data!$P$2:$P$61,$T42)) -> ✓ Complete | Q42: =IF($T42="","",INDEX(Data!$W$2:$W$61,$T42)) | R42: =IF($T42="","",INDEX(Data!$Q$2:$Q$61,$T42)) | S42: =IF($T42="","",INDEX(Data!$R$2:$R$61,$T42)) -> 0 | T42: =IFERROR(MATCH(15,Data!$V$2:$V$61,0),"") -> 15
B43: =IF($T43="","",HYPERLINK("#'"&INDEX(Data!$B$2:$B$61,$T43)&"'!G"&INDEX(Data!$C$2:$C$61,$T43),"✎")) -> ✎ | C43: =IF($T43="","",INDEX(Data!$A$2:$A$61,$T43)) -> Dan Lowe - Design Lead | D43: =IF($T43="","",INDEX(Data!$D$2:$D$61,$T43)) -> A1160 | E43: =IF($T43="","",INDEX(Data!$E$2:$E$61,$T43)) -> Design package 16 | F43: =IF($T43="","",INDEX(Data!$F$2:$F$61,$T43)) -> Engineering | G43: =IF($T43="","",INDEX(Data!$G$2:$G$61,$T43)) -> Completed | H43: =IF($T43="","",INDEX(Data!$H$2:$H$61,$T43)) -> 45337 | I43: =IF($T43="","",INDEX(Data!$I$2:$I$61,$T43)) -> 45351 | J43: =IF($T43="","",INDEX(Data!$J$2:$J$61,$T43)) -> 100 | K43: =IF($T43="","",INDEX(Data!$K$2:$K$61,$T43)) -> 45337 | L43: =IF($T43="","",INDEX(Data!$L$2:$L$61,$T43)) -> 45351 | M43: =IF($T43="","",INDEX(Data!$M$2:$M$61,$T43)) | N43: =IF($T43="","",INDEX(Data!$N$2:$N$61,$T43)) | O43: =IF($T43="","",INDEX(Data!$O$2:$O$61,$T43)) -> 0 | P43: =IF($T43="","",INDEX(Data!$P$2:$P$61,$T43)) -> ✓ Complete | Q43: =IF($T43="","",INDEX(Data!$W$2:$W$61,$T43)) | R43: =IF($T43="","",INDEX(Data!$Q$2:$Q$61,$T43)) | S43: =IF($T43="","",INDEX(Data!$R$2:$R$61,$T43)) -> 0 | T43: =IFERROR(MATCH(16,Data!$V$2:$V$61,0),"") -> 16
B44: =IF($T44="","",HYPERLINK("#'"&INDEX(Data!$B$2:$B$61,$T44)&"'!G"&INDEX(Data!$C$2:$C$61,$T44),"✎")) -> ✎ | C44: =IF($T44="","",INDEX(Data!$A$2:$A$61,$T44)) -> Dan Lowe - Design Lead | D44: =IF($T44="","",INDEX(Data!$D$2:$D$61,$T44)) -> A1170 | E44: =IF($T44="","",INDEX(Data!$E$2:$E$61,$T44)) -> Design package 17 | F44: =IF($T44="","",INDEX(Data!$F$2:$F$61,$T44)) -> Engineering | G44: =IF($T44="","",INDEX(Data!$G$2:$G$61,$T44)) -> Completed | H44: =IF($T44="","",INDEX(Data!$H$2:$H$61,$T44)) -> 45344 | I44: =IF($T44="","",INDEX(Data!$I$2:$I$61,$T44)) -> 45358 | J44: =IF($T44="","",INDEX(Data!$J$2:$J$61,$T44)) -> 100 | K44: =IF($T44="","",INDEX(Data!$K$2:$K$61,$T44)) -> 45344 | L44: =IF($T44="","",INDEX(Data!$L$2:$L$61,$T44)) -> 45358 | M44: =IF($T44="","",INDEX(Data!$M$2:$M$61,$T44)) | N44: =IF($T44="","",INDEX(Data!$N$2:$N$61,$T44)) | O44: =IF($T44="","",INDEX(Data!$O$2:$O$61,$T44)) -> 0 | P44: =IF($T44="","",INDEX(Data!$P$2:$P$61,$T44)) -> ✓ Complete | Q44: =IF($T44="","",INDEX(Data!$W$2:$W$61,$T44)) | R44: =IF($T44="","",INDEX(Data!$Q$2:$Q$61,$T44)) | S44: =IF($T44="","",INDEX(Data!$R$2:$R$61,$T44)) -> 0 | T44: =IFERROR(MATCH(17,Data!$V$2:$V$61,0),"") -> 17
B45: =IF($T45="","",HYPERLINK("#'"&INDEX(Data!$B$2:$B$61,$T45)&"'!G"&INDEX(Data!$C$2:$C$61,$T45),"✎")) -> ✎ | C45: =IF($T45="","",INDEX(Data!$A$2:$A$61,$T45)) -> Dan Lowe - Design Lead | D45: =IF($T45="","",INDEX(Data!$D$2:$D$61,$T45)) -> A1180 | E45: =IF($T45="","",INDEX(Data!$E$2:$E$61,$T45)) -> Design package 18 | F45: =IF($T45="","",INDEX(Data!$F$2:$F$61,$T45)) -> Engineering | G45: =IF($T45="","",INDEX(Data!$G$2:$G$61,$T45)) -> Completed | H45: =IF($T45="","",INDEX(Data!$H$2:$H$61,$T45)) -> 45351 | I45: =IF($T45="","",INDEX(Data!$I$2:$I$61,$T45)) -> 45354 | J45: =IF($T45="","",INDEX(Data!$J$2:$J$61,$T45)) -> 100 | K45: =IF($T45="","",INDEX(Data!$K$2:$K$61,$T45)) -> 45351 | L45: =IF($T45="","",INDEX(Data!$L$2:$L$61,$T45)) -> 45354 | M45: =IF($T45="","",INDEX(Data!$M$2:$M$61,$T45)) | N45: =IF($T45="","",INDEX(Data!$N$2:$N$61,$T45)) | O45: =IF($T45="","",INDEX(Data!$O$2:$O$61,$T45)) -> 0 | P45: =IF($T45="","",INDEX(Data!$P$2:$P$61,$T45)) -> ✓ Complete | Q45: =IF($T45="","",INDEX(Data!$W$2:$W$61,$T45)) | R45: =IF($T45="","",INDEX(Data!$Q$2:$Q$61,$T45)) | S45: =IF($T45="","",INDEX(Data!$R$2:$R$61,$T45)) -> 0 | T45: =IFERROR(MATCH(18,Data!$V$2:$V$61,0),"") -> 18
B46: =IF($T46="","",HYPERLINK("#'"&INDEX(Data!$B$2:$B$61,$T46)&"'!G"&INDEX(Data!$C$2:$C$61,$T46),"✎")) -> ✎ | C46: =IF($T46="","",INDEX(Data!$A$2:$A$61,$T46)) -> Dan Lowe - Design Lead | D46: =IF($T46="","",INDEX(Data!$D$2:$D$61,$T46)) -> A1190 | E46: =IF($T46="","",INDEX(Data!$E$2:$E$61,$T46)) -> Design package 19 | F46: =IF($T46="","",INDEX(Data!$F$2:$F$61,$T46)) -> Engineering | G46: =IF($T46="","",INDEX(Data!$G$2:$G$61,$T46)) -> Completed | H46: =IF($T46="","",INDEX(Data!$H$2:$H$61,$T46)) -> 45352 | I46: =IF($T46="","",INDEX(Data!$I$2:$I$61,$T46)) -> 45359 | J46: =IF($T46="","",INDEX(Data!$J$2:$J$61,$T46)) -> 100 | K46: =IF($T46="","",INDEX(Data!$K$2:$K$61,$T46)) -> 45352 | L46: =IF($T46="","",INDEX(Data!$L$2:$L$61,$T46)) -> 45359 | M46: =IF($T46="","",INDEX(Data!$M$2:$M$61,$T46)) | N46: =IF($T46="","",INDEX(Data!$N$2:$N$61,$T46)) | O46: =IF($T46="","",INDEX(Data!$O$2:$O$61,$T46)) -> 0 | P46: =IF($T46="","",INDEX(Data!$P$2:$P$61,$T46)) -> ✓ Complete | Q46: =IF($T46="","",INDEX(Data!$W$2:$W$61,$T46)) | R46: =IF($T46="","",INDEX(Data!$Q$2:$Q$61,$T46)) | S46: =IF($T46="","",INDEX(Data!$R$2:$R$61,$T46)) -> 0 | T46: =IFERROR(MATCH(19,Data!$V$2:$V$61,0),"") -> 19
B47: =IF($T47="","",HYPERLINK("#'"&INDEX(Data!$B$2:$B$61,$T47)&"'!G"&INDEX(Data!$C$2:$C$61,$T47),"✎")) -> ✎ | C47: =IF($T47="","",INDEX(Data!$A$2:$A$61,$T47)) -> Priya Menon - Project Manager | D47: =IF($T47="","",INDEX(Data!$D$2:$D$61,$T47)) -> A1000 | E47: =IF($T47="","",INDEX(Data!$E$2:$E$61,$T47)) -> Design package 00 | F47: =IF($T47="","",INDEX(Data!$F$2:$F$61,$T47)) -> Engineering | G47: =IF($T47="","",INDEX(Data!$G$2:$G$61,$T47)) -> Completed | H47: =IF($T47="","",INDEX(Data!$H$2:$H$61,$T47)) -> 45293 | I47: =IF($T47="","",INDEX(Data!$I$2:$I$61,$T47)) -> 45300 | J47: =IF($T47="","",INDEX(Data!$J$2:$J$61,$T47)) -> 100 | K47: =IF($T47="","",INDEX(Data!$K$2:$K$61,$T47)) -> 45293 | L47: =IF($T47="","",INDEX(Data!$L$2:$L$61,$T47)) -> 45300 | M47: =IF($T47="","",INDEX(Data!$M$2:$M$61,$T47)) | N47: =IF($T47="","",INDEX(Data!$N$2:$N$61,$T47)) | O47: =IF($T47="","",INDEX(Data!$O$2:$O$61,$T47)) -> 0 | P47: =IF($T47="","",INDEX(Data!$P$2:$P$61,$T47)) -> ✓ Complete | Q47: =IF($T47="","",INDEX(Data!$W$2:$W$61,$T47)) | R47: =IF($T47="","",INDEX(Data!$Q$2:$Q$61,$T47)) | S47: =IF($T47="","",INDEX(Data!$R$2:$R$61,$T47)) -> 0 | T47: =IFERROR(MATCH(20,Data!$V$2:$V$61,0),"") -> 20
B48: =IF($T48="","",HYPERLINK("#'"&INDEX(Data!$B$2:$B$61,$T48)&"'!G"&INDEX(Data!$C$2:$C$61,$T48),"✎")) -> ✎ | C48: =IF($T48="","",INDEX(Data!$A$2:$A$61,$T48)) -> Priya Menon - Project Manager | D48: =IF($T48="","",INDEX(Data!$D$2:$D$61,$T48)) -> A1590 | E48: =IF($T48="","",INDEX(Data!$E$2:$E$61,$T48)) -> Build package 59 | F48: =IF($T48="","",INDEX(Data!$F$2:$F$61,$T48)) -> Construction | G48: =IF($T48="","",INDEX(Data!$G$2:$G$61,$T48)) -> Not Started | H48: =IF($T48="","",INDEX(Data!$H$2:$H$61,$T48)) -> 45660 | I48: =IF($T48="","",INDEX(Data!$I$2:$I$61,$T48)) -> 45681 | J48: =IF($T48="","",INDEX(Data!$J$2:$J$61,$T48)) -> 0 | K48: =IF($T48="","",INDEX(Data!$K$2:$K$61,$T48)) | L48: =IF($T48="","",INDEX(Data!$L$2:$L$61,$T48)) | M48: =IF($T48="","",INDEX(Data!$M$2:$M$61,$T48)) | N48: =IF($T48="","",INDEX(Data!$N$2:$N$61,$T48)) | O48: =IF($T48="","",INDEX(Data!$O$2:$O$61,$T48)) -> 0 | P48: =IF($T48="","",INDEX(Data!$P$2:$P$61,$T48)) -> Not changed yet | Q48: =IF($T48="","",INDEX(Data!$W$2:$W$61,$T48)) | R48: =IF($T48="","",INDEX(Data!$Q$2:$Q$61,$T48)) | S48: =IF($T48="","",INDEX(Data!$R$2:$R$61,$T48)) -> 0 | T48: =IFERROR(MATCH(21,Data!$V$2:$V$61,0),"") -> 21
B49: =IF($T49="","",HYPERLINK("#'"&INDEX(Data!$B$2:$B$61,$T49)&"'!G"&INDEX(Data!$C$2:$C$61,$T49),"✎")) -> ✎ | C49: =IF($T49="","",INDEX(Data!$A$2:$A$61,$T49)) -> Sara Moss - Site Manager | D49: =IF($T49="","",INDEX(Data!$D$2:$D$61,$T49)) -> A1200 | E49: =IF($T49="","",INDEX(Data!$E$2:$E$61,$T49)) -> Build package 20 | F49: =IF($T49="","",INDEX(Data!$F$2:$F$61,$T49)) -> Construction | G49: =IF($T49="","",INDEX(Data!$G$2:$G$61,$T49)) -> Completed | H49: =IF($T49="","",INDEX(Data!$H$2:$H$61,$T49)) -> 45355 | I49: =IF($T49="","",INDEX(Data!$I$2:$I$61,$T49)) -> 45369 | J49: =IF($T49="","",INDEX(Data!$J$2:$J$61,$T49)) -> 100 | K49: =IF($T49="","",INDEX(Data!$K$2:$K$61,$T49)) -> 45355 | L49: =IF($T49="","",INDEX(Data!$L$2:$L$61,$T49)) -> 45369 | M49: =IF($T49="","",INDEX(Data!$M$2:$M$61,$T49)) | N49: =IF($T49="","",INDEX(Data!$N$2:$N$61,$T49)) | O49: =IF($T49="","",INDEX(Data!$O$2:$O$61,$T49)) -> 0 | P49: =IF($T49="","",INDEX(Data!$P$2:$P$61,$T49)) -> ✓ Complete | Q49: =IF($T49="","",INDEX(Data!$W$2:$W$61,$T49)) | R49: =IF($T49="","",INDEX(Data!$Q$2:$Q$61,$T49)) | S49: =IF($T49="","",INDEX(Data!$R$2:$R$61,$T49)) -> 0 | T49: =IFERROR(MATCH(22,Data!$V$2:$V$61,0),"") -> 22
B50: =IF($T50="","",HYPERLINK("#'"&INDEX(Data!$B$2:$B$61,$T50)&"'!G"&INDEX(Data!$C$2:$C$61,$T50),"✎")) -> ✎ | C50: =IF($T50="","",INDEX(Data!$A$2:$A$61,$T50)) -> Sara Moss - Site Manager | D50: =IF($T50="","",INDEX(Data!$D$2:$D$61,$T50)) -> A1220 | E50: =IF($T50="","",INDEX(Data!$E$2:$E$61,$T50)) -> Build package 22 | F50: =IF($T50="","",INDEX(Data!$F$2:$F$61,$T50)) -> Construction | G50: =IF($T50="","",INDEX(Data!$G$2:$G$61,$T50)) -> Completed | H50: =IF($T50="","",INDEX(Data!$H$2:$H$61,$T50)) -> 45369 | I50: =IF($T50="","",INDEX(Data!$I$2:$I$61,$T50)) -> 45383 | J50: =IF($T50="","",INDEX(Data!$J$2:$J$61,$T50)) -> 100 | K50: =IF($T50="","",INDEX(Data!$K$2:$K$61,$T50)) -> 45369 | L50: =IF($T50="","",INDEX(Data!$L$2:$L$61,$T50)) -> 45383 | M50: =IF($T50="","",INDEX(Data!$M$2:$M$61,$T50)) | N50: =IF($T50="","",INDEX(Data!$N$2:$N$61,$T50)) | O50: =IF($T50="","",INDEX(Data!$O$2:$O$61,$T50)) -> 0 | P50: =IF($T50="","",INDEX(Data!$P$2:$P$61,$T50)) -> ✓ Complete | Q50: =IF($T50="","",INDEX(Data!$W$2:$W$61,$T50)) | R50: =IF($T50="","",INDEX(Data!$Q$2:$Q$61,$T50)) | S50: =IF($T50="","",INDEX(Data!$R$2:$R$61,$T50)) -> 0 | T50: =IFERROR(MATCH(23,Data!$V$2:$V$61,0),"") -> 23
...

Sheet Dan Lowe
A1: Programme update · Dan Lowe - Design Lead
A2: SAMPLE-FITOUT · data date 30 Jun 2024 · Whole programme
A3: =IF(INFO("RECALC")="Automatic","","If these figures are struck through, or do not follow what is typed, Excel is calculating manually: press F9 to update them, or turn it on for good with Formulas › Calculation Options › Automatic.") -> If these figures are struck through, or do not follow what is typed, Excel is calculating manually: press F9 to update them, or turn it on for good with Formulas › Calculation Options › Automatic.
A4: 1 Type in the white columns only; grey is the programme, locked. Type dates like 14 Oct 2026. 2 Actual start / finish: dates that have happened - type over the programme's. Not finished yet? Leave Actual finish empty and give an Expected finish. 3 Finishing late? Give a delay cause or a note. Check says what is still needed. | C4: ACTIVITIES | E4: UPDATED | G4: NEED SOMETHING FROM YOU | J4: FINISHING LATE | L4: Grey: the programme | M4: =HYPERLINK("#Overview!C5","‹ Overview") -> ‹ Overview
C5: =COUNTA($P$10:$P$29) -> 19 | E5: =SUM($X$10:$X$29) -> 0 | G5: =COUNTIF($O$10:$O$29,"Reason needed")+COUNTIF($O$10:$O$29,"Start date needed")+COUNTIF($O$10:$O$29,"Finish date needed")+COUNTIF($O$10:$O$29,"Date in the future") -> 0 | J5: =COUNTIFS($N$10:$N$29,">0",$H$10:$H$29,"") -> 0 | L5: White: your update | M5: Red in Check: still needed
C6: ="in this update" -> in this update | E6: =IFERROR(TEXT(SUM($X$10:$X$29)/COUNTA($P$10:$P$29),"0%"),"0%")&" done" -> 0% done | G6: ="red in the Check column" -> red in the Check column | J6: ="not finished, past the planned finish" -> not finished, past the planned finish | L6: Green: you changed it | M6: Bold red ID: critical
A8: THE PROGRAMME (locked) | G8: YOUR UPDATE | M8: CHECK
A9: Activity ID | B9: Activity name | C9: Start | D9: Finish | E9: Float (d) | F9: Physical % complete | G9: Actual start | H9: Actual finish | I9: Actual % complete | J9: Expected finish | K9: Delay cause | L9: Notes | M9: Finish moves (d) | N9: Days late | O9: Check | P9: Status | Q9: Critical | R9: Planned start | S9: Compare finish | T9: was actual start | U9: was actual finish | V9: was actual % | W9: was expected finish | X9: changed | Y9: WBS level | Z9: Planned finish
A10: ENG Engineering | Y10: 1
A11: A1010 | B11: Design package 01 | C11: 45296 | D11: 45307 | E11: 0 | F11: 100 | G11: 45296 | H11: 45307 | M11: =IFERROR(IF(OR(D11="",IF(H11<>"",H11,IF(J11<>"",J11,D11))=""),"",IF(H11<>"",H11,IF(J11<>"",J11,D11))-D11),"") -> 0 | N11: =IFERROR(IF(OR(S11="",IF(H11<>"",H11,IF(J11<>"",J11,D11))=""),"",MAX(0,IF(H11<>"",H11,IF(J11<>"",J11,D11))-S11)),"") -> 0 | O11: =IF(OR(AND(G11<>"",NOT(ISNUMBER(G11))),AND(H11<>"",NOT(ISNUMBER(H11))),AND(J11<>"",NOT(ISNUMBER(J11)))),"Not a date",IF(OR(AND(G11<>"",N(G11)>TODAY()),AND(H11<>"",N(H11)>TODAY())),"Date in the future",IF(H11<>"",IF(G11="","Start date needed","✓ Complete"),IF(AND(IF(H11<>"",H11,IF(J11<>"",J11,D11))<>"",S11<>"",IF(H11<>"",H11,IF(J11<>"",J11,D11))>S11,K11="",L11=""),"Reason needed",IF(AND(G11="",OR(N(I11)>0,AND(C11<>"",C11<DATE(2024,6,30),X11=0))),"Start date needed",IF(AND(IF(H11<>"",H11,IF(J11<>"",J11,D11))<>"",IF(H11<>"",H11,IF(J11<>"",J11,D11))<DATE(2024,6,30)),"Finish date needed",IF(X11=1,"✓ Updated","Not changed yet"))))))) -> ✓ Complete | P11: Completed | R11: 45296 | S11: 45307 | T11: 45296 | U11: 45307 | X11: =IF(OR(G11<>T11,H11<>U11,I11<>V11,J11<>W11,K11<>"",L11<>""),1,0) -> 0 | Z11: 45307
A12: A1020 | B12: Design package 02 | C12: 45301 | D12: 45304 | E12: 0 | F12: 100 | G12: 45301 | H12: 45304 | M12: =IFERROR(IF(OR(D12="",IF(H12<>"",H12,IF(J12<>"",J12,D12))=""),"",IF(H12<>"",H12,IF(J12<>"",J12,D12))-D12),"") -> 0 | N12: =IFERROR(IF(OR(S12="",IF(H12<>"",H12,IF(J12<>"",J12,D12))=""),"",MAX(0,IF(H12<>"",H12,IF(J12<>"",J12,D12))-S12)),"") -> 0 | O12: =IF(OR(AND(G12<>"",NOT(ISNUMBER(G12))),AND(H12<>"",NOT(ISNUMBER(H12))),AND(J12<>"",NOT(ISNUMBER(J12)))),"Not a date",IF(OR(AND(G12<>"",N(G12)>TODAY()),AND(H12<>"",N(H12)>TODAY())),"Date in the future",IF(H12<>"",IF(G12="","Start date needed","✓ Complete"),IF(AND(IF(H12<>"",H12,IF(J12<>"",J12,D12))<>"",S12<>"",IF(H12<>"",H12,IF(J12<>"",J12,D12))>S12,K12="",L12=""),"Reason needed",IF(AND(G12="",OR(N(I12)>0,AND(C12<>"",C12<DATE(2024,6,30),X12=0))),"Start date needed",IF(AND(IF(H12<>"",H12,IF(J12<>"",J12,D12))<>"",IF(H12<>"",H12,IF(J12<>"",J12,D12))<DATE(2024,6,30)),"Finish date needed",IF(X12=1,"✓ Updated","Not changed yet"))))))) -> ✓ Complete | P12: Completed | R12: 45301 | S12: 45304 | T12: 45301 | U12: 45304 | X12: =IF(OR(G12<>T12,H12<>U12,I12<>V12,J12<>W12,K12<>"",L12<>""),1,0) -> 0 | Z12: 45304
A13: A1030 | B13: Design package 03 | C13: 45302 | D13: 45309 | E13: 0 | F13: 100 | G13: 45302 | H13: 45309 | M13: =IFERROR(IF(OR(D13="",IF(H13<>"",H13,IF(J13<>"",J13,D13))=""),"",IF(H13<>"",H13,IF(J13<>"",J13,D13))-D13),"") -> 0 | N13: =IFERROR(IF(OR(S13="",IF(H13<>"",H13,IF(J13<>"",J13,D13))=""),"",MAX(0,IF(H13<>"",H13,IF(J13<>"",J13,D13))-S13)),"") -> 0 | O13: =IF(OR(AND(G13<>"",NOT(ISNUMBER(G13))),AND(H13<>"",NOT(ISNUMBER(H13))),AND(J13<>"",NOT(ISNUMBER(J13)))),"Not a date",IF(OR(AND(G13<>"",N(G13)>TODAY()),AND(H13<>"",N(H13)>TODAY())),"Date in the future",IF(H13<>"",IF(G13="","Start date needed","✓ Complete"),IF(AND(IF(H13<>"",H13,IF(J13<>"",J13,D13))<>"",S13<>"",IF(H13<>"",H13,IF(J13<>"",J13,D13))>S13,K13="",L13=""),"Reason needed",IF(AND(G13="",OR(N(I13)>0,AND(C13<>"",C13<DATE(2024,6,30),X13=0))),"Start date needed",IF(AND(IF(H13<>"",H13,IF(J13<>"",J13,D13))<>"",IF(H13<>"",H13,IF(J13<>"",J13,D13))<DATE(2024,6,30)),"Finish date needed",IF(X13=1,"✓ Updated","Not changed yet"))))))) -> ✓ Complete | P13: Completed | R13: 45302 | S13: 45309 | T13: 45302 | U13: 45309 | X13: =IF(OR(G13<>T13,H13<>U13,I13<>V13,J13<>W13,K13<>"",L13<>""),1,0) -> 0 | Z13: 45309
A14: A1040 | B14: Design package 04 | C14: 45305 | D14: 45319 | E14: 1 | F14: 100 | G14: 45305 | H14: 45319 | M14: =IFERROR(IF(OR(D14="",IF(H14<>"",H14,IF(J14<>"",J14,D14))=""),"",IF(H14<>"",H14,IF(J14<>"",J14,D14))-D14),"") -> 0 | N14: =IFERROR(IF(OR(S14="",IF(H14<>"",H14,IF(J14<>"",J14,D14))=""),"",MAX(0,IF(H14<>"",H14,IF(J14<>"",J14,D14))-S14)),"") -> 0 | O14: =IF(OR(AND(G14<>"",NOT(ISNUMBER(G14))),AND(H14<>"",NOT(ISNUMBER(H14))),AND(J14<>"",NOT(ISNUMBER(J14)))),"Not a date",IF(OR(AND(G14<>"",N(G14)>TODAY()),AND(H14<>"",N(H14)>TODAY())),"Date in the future",IF(H14<>"",IF(G14="","Start date needed","✓ Complete"),IF(AND(IF(H14<>"",H14,IF(J14<>"",J14,D14))<>"",S14<>"",IF(H14<>"",H14,IF(J14<>"",J14,D14))>S14,K14="",L14=""),"Reason needed",IF(AND(G14="",OR(N(I14)>0,AND(C14<>"",C14<DATE(2024,6,30),X14=0))),"Start date needed",IF(AND(IF(H14<>"",H14,IF(J14<>"",J14,D14))<>"",IF(H14<>"",H14,IF(J14<>"",J14,D14))<DATE(2024,6,30)),"Finish date needed",IF(X14=1,"✓ Updated","Not changed yet"))))))) -> ✓ Complete | P14: Completed | R14: 45305 | S14: 45319 | T14: 45305 | U14: 45319 | X14: =IF(OR(G14<>T14,H14<>U14,I14<>V14,J14<>W14,K14<>"",L14<>""),1,0) -> 0 | Z14: 45319
A15: A1050 | B15: Design package 05 | C15: 45312 | D15: 45315 | E15: 0 | F15: 100 | G15: 45312 | H15: 45315 | M15: =IFERROR(IF(OR(D15="",IF(H15<>"",H15,IF(J15<>"",J15,D15))=""),"",IF(H15<>"",H15,IF(J15<>"",J15,D15))-D15),"") -> 0 | N15: =IFERROR(IF(OR(S15="",IF(H15<>"",H15,IF(J15<>"",J15,D15))=""),"",MAX(0,IF(H15<>"",H15,IF(J15<>"",J15,D15))-S15)),"") -> 0 | O15: =IF(OR(AND(G15<>"",NOT(ISNUMBER(G15))),AND(H15<>"",NOT(ISNUMBER(H15))),AND(J15<>"",NOT(ISNUMBER(J15)))),"Not a date",IF(OR(AND(G15<>"",N(G15)>TODAY()),AND(H15<>"",N(H15)>TODAY())),"Date in the future",IF(H15<>"",IF(G15="","Start date needed","✓ Complete"),IF(AND(IF(H15<>"",H15,IF(J15<>"",J15,D15))<>"",S15<>"",IF(H15<>"",H15,IF(J15<>"",J15,D15))>S15,K15="",L15=""),"Reason needed",IF(AND(G15="",OR(N(I15)>0,AND(C15<>"",C15<DATE(2024,6,30),X15=0))),"Start date needed",IF(AND(IF(H15<>"",H15,IF(J15<>"",J15,D15))<>"",IF(H15<>"",H15,IF(J15<>"",J15,D15))<DATE(2024,6,30)),"Finish date needed",IF(X15=1,"✓ Updated","Not changed yet"))))))) -> ✓ Complete | P15: Completed | R15: 45312 | S15: 45315 | T15: 45312 | U15: 45315 | X15: =IF(OR(G15<>T15,H15<>U15,I15<>V15,J15<>W15,K15<>"",L15<>""),1,0) -> 0 | Z15: 45315
A16: A1060 | B16: Design package 06 | C16: 45313 | D16: 45324 | E16: 50 | F16: 100 | G16: 45313 | H16: 45324 | M16: =IFERROR(IF(OR(D16="",IF(H16<>"",H16,IF(J16<>"",J16,D16))=""),"",IF(H16<>"",H16,IF(J16<>"",J16,D16))-D16),"") -> 0 | N16: =IFERROR(IF(OR(S16="",IF(H16<>"",H16,IF(J16<>"",J16,D16))=""),"",MAX(0,IF(H16<>"",H16,IF(J16<>"",J16,D16))-S16)),"") -> 0 | O16: =IF(OR(AND(G16<>"",NOT(ISNUMBER(G16))),AND(H16<>"",NOT(ISNUMBER(H16))),AND(J16<>"",NOT(ISNUMBER(J16)))),"Not a date",IF(OR(AND(G16<>"",N(G16)>TODAY()),AND(H16<>"",N(H16)>TODAY())),"Date in the future",IF(H16<>"",IF(G16="","Start date needed","✓ Complete"),IF(AND(IF(H16<>"",H16,IF(J16<>"",J16,D16))<>"",S16<>"",IF(H16<>"",H16,IF(J16<>"",J16,D16))>S16,K16="",L16=""),"Reason needed",IF(AND(G16="",OR(N(I16)>0,AND(C16<>"",C16<DATE(2024,6,30),X16=0))),"Start date needed",IF(AND(IF(H16<>"",H16,IF(J16<>"",J16,D16))<>"",IF(H16<>"",H16,IF(J16<>"",J16,D16))<DATE(2024,6,30)),"Finish date needed",IF(X16=1,"✓ Updated","Not changed yet"))))))) -> ✓ Complete | P16: Completed | R16: 45313 | S16: 45324 | T16: 45313 | U16: 45324 | X16: =IF(OR(G16<>T16,H16<>U16,I16<>V16,J16<>W16,K16<>"",L16<>""),1,0) -> 0 | Z16: 45324
A17: A1070 | B17: Design package 07 | C17: 45318 | D17: 45321 | E17: 1 | F17: 100 | G17: 45318 | H17: 45321 | M17: =IFERROR(IF(OR(D17="",IF(H17<>"",H17,IF(J17<>"",J17,D17))=""),"",IF(H17<>"",H17,IF(J17<>"",J17,D17))-D17),"") -> 0 | N17: =IFERROR(IF(OR(S17="",IF(H17<>"",H17,IF(J17<>"",J17,D17))=""),"",MAX(0,IF(H17<>"",H17,IF(J17<>"",J17,D17))-S17)),"") -> 0 | O17: =IF(OR(AND(G17<>"",NOT(ISNUMBER(G17))),AND(H17<>"",NOT(ISNUMBER(H17))),AND(J17<>"",NOT(ISNUMBER(J17)))),"Not a date",IF(OR(AND(G17<>"",N(G17)>TODAY()),AND(H17<>"",N(H17)>TODAY())),"Date in the future",IF(H17<>"",IF(G17="","Start date needed","✓ Complete"),IF(AND(IF(H17<>"",H17,IF(J17<>"",J17,D17))<>"",S17<>"",IF(H17<>"",H17,IF(J17<>"",J17,D17))>S17,K17="",L17=""),"Reason needed",IF(AND(G17="",OR(N(I17)>0,AND(C17<>"",C17<DATE(2024,6,30),X17=0))),"Start date needed",IF(AND(IF(H17<>"",H17,IF(J17<>"",J17,D17))<>"",IF(H17<>"",H17,IF(J17<>"",J17,D17))<DATE(2024,6,30)),"Finish date needed",IF(X17=1,"✓ Updated","Not changed yet"))))))) -> ✓ Complete | P17: Completed | R17: 45318 | S17: 45321 | T17: 45318 | U17: 45321 | X17: =IF(OR(G17<>T17,H17<>U17,I17<>V17,J17<>W17,K17<>"",L17<>""),1,0) -> 0 | Z17: 45321
A18: A1080 | B18: Design package 08 | C18: 45319 | D18: 45322 | E18: 50 | F18: 100 | G18: 45319 | H18: 45322 | M18: =IFERROR(IF(OR(D18="",IF(H18<>"",H18,IF(J18<>"",J18,D18))=""),"",IF(H18<>"",H18,IF(J18<>"",J18,D18))-D18),"") -> 0 | N18: =IFERROR(IF(OR(S18="",IF(H18<>"",H18,IF(J18<>"",J18,D18))=""),"",MAX(0,IF(H18<>"",H18,IF(J18<>"",J18,D18))-S18)),"") -> 0 | O18: =IF(OR(AND(G18<>"",NOT(ISNUMBER(G18))),AND(H18<>"",NOT(ISNUMBER(H18))),AND(J18<>"",NOT(ISNUMBER(J18)))),"Not a date",IF(OR(AND(G18<>"",N(G18)>TODAY()),AND(H18<>"",N(H18)>TODAY())),"Date in the future",IF(H18<>"",IF(G18="","Start date needed","✓ Complete"),IF(AND(IF(H18<>"",H18,IF(J18<>"",J18,D18))<>"",S18<>"",IF(H18<>"",H18,IF(J18<>"",J18,D18))>S18,K18="",L18=""),"Reason needed",IF(AND(G18="",OR(N(I18)>0,AND(C18<>"",C18<DATE(2024,6,30),X18=0))),"Start date needed",IF(AND(IF(H18<>"",H18,IF(J18<>"",J18,D18))<>"",IF(H18<>"",H18,IF(J18<>"",J18,D18))<DATE(2024,6,30)),"Finish date needed",IF(X18=1,"✓ Updated","Not changed yet"))))))) -> ✓ Complete | P18: Completed | R18: 45319 | S18: 45322 | T18: 45319 | U18: 45322 | X18: =IF(OR(G18<>T18,H18<>U18,I18<>V18,J18<>W18,K18<>"",L18<>""),1,0) -> 0 | Z18: 45322
A19: A1090 | B19: Design package 09 | C19: 45320 | D19: 45323 | E19: 0 | F19: 100 | G19: 45320 | H19: 45323 | M19: =IFERROR(IF(OR(D19="",IF(H19<>"",H19,IF(J19<>"",J19,D19))=""),"",IF(H19<>"",H19,IF(J19<>"",J19,D19))-D19),"") -> 0 | N19: =IFERROR(IF(OR(S19="",IF(H19<>"",H19,IF(J19<>"",J19,D19))=""),"",MAX(0,IF(H19<>"",H19,IF(J19<>"",J19,D19))-S19)),"") -> 0 | O19: =IF(OR(AND(G19<>"",NOT(ISNUMBER(G19))),AND(H19<>"",NOT(ISNUMBER(H19))),AND(J19<>"",NOT(ISNUMBER(J19)))),"Not a date",IF(OR(AND(G19<>"",N(G19)>TODAY()),AND(H19<>"",N(H19)>TODAY())),"Date in the future",IF(H19<>"",IF(G19="","Start date needed","✓ Complete"),IF(AND(IF(H19<>"",H19,IF(J19<>"",J19,D19))<>"",S19<>"",IF(H19<>"",H19,IF(J19<>"",J19,D19))>S19,K19="",L19=""),"Reason needed",IF(AND(G19="",OR(N(I19)>0,AND(C19<>"",C19<DATE(2024,6,30),X19=0))),"Start date needed",IF(AND(IF(H19<>"",H19,IF(J19<>"",J19,D19))<>"",IF(H19<>"",H19,IF(J19<>"",J19,D19))<DATE(2024,6,30)),"Finish date needed",IF(X19=1,"✓ Updated","Not changed yet"))))))) -> ✓ Complete | P19: Completed | R19: 45320 | S19: 45323 | T19: 45320 | U19: 45323 | X19: =IF(OR(G19<>T19,H19<>U19,I19<>V19,J19<>W19,K19<>"",L19<>""),1,0) -> 0 | Z19: 45323
A20: A1100 | B20: Design package 10 | C20: 45321 | D20: 45325 | E20: 0 | F20: 100 | G20: 45321 | H20: 45325 | M20: =IFERROR(IF(OR(D20="",IF(H20<>"",H20,IF(J20<>"",J20,D20))=""),"",IF(H20<>"",H20,IF(J20<>"",J20,D20))-D20),"") -> 0 | N20: =IFERROR(IF(OR(S20="",IF(H20<>"",H20,IF(J20<>"",J20,D20))=""),"",MAX(0,IF(H20<>"",H20,IF(J20<>"",J20,D20))-S20)),"") -> 0 | O20: =IF(OR(AND(G20<>"",NOT(ISNUMBER(G20))),AND(H20<>"",NOT(ISNUMBER(H20))),AND(J20<>"",NOT(ISNUMBER(J20)))),"Not a date",IF(OR(AND(G20<>"",N(G20)>TODAY()),AND(H20<>"",N(H20)>TODAY())),"Date in the future",IF(H20<>"",IF(G20="","Start date needed","✓ Complete"),IF(AND(IF(H20<>"",H20,IF(J20<>"",J20,D20))<>"",S20<>"",IF(H20<>"",H20,IF(J20<>"",J20,D20))>S20,K20="",L20=""),"Reason needed",IF(AND(G20="",OR(N(I20)>0,AND(C20<>"",C20<DATE(2024,6,30),X20=0))),"Start date needed",IF(AND(IF(H20<>"",H20,IF(J20<>"",J20,D20))<>"",IF(H20<>"",H20,IF(J20<>"",J20,D20))<DATE(2024,6,30)),"Finish date needed",IF(X20=1,"✓ Updated","Not changed yet"))))))) -> ✓ Complete | P20: Completed | R20: 45321 | S20: 45325 | T20: 45321 | U20: 45325 | X20: =IF(OR(G20<>T20,H20<>U20,I20<>V20,J20<>W20,K20<>"",L20<>""),1,0) -> 0 | Z20: 45325
A21: A1110 | B21: Design package 11 | C21: 45323 | D21: 45337 | E21: 50 | F21: 100 | G21: 45323 | H21: 45337 | M21: =IFERROR(IF(OR(D21="",IF(H21<>"",H21,IF(J21<>"",J21,D21))=""),"",IF(H21<>"",H21,IF(J21<>"",J21,D21))-D21),"") -> 0 | N21: =IFERROR(IF(OR(S21="",IF(H21<>"",H21,IF(J21<>"",J21,D21))=""),"",MAX(0,IF(H21<>"",H21,IF(J21<>"",J21,D21))-S21)),"") -> 0 | O21: =IF(OR(AND(G21<>"",NOT(ISNUMBER(G21))),AND(H21<>"",NOT(ISNUMBER(H21))),AND(J21<>"",NOT(ISNUMBER(J21)))),"Not a date",IF(OR(AND(G21<>"",N(G21)>TODAY()),AND(H21<>"",N(H21)>TODAY())),"Date in the future",IF(H21<>"",IF(G21="","Start date needed","✓ Complete"),IF(AND(IF(H21<>"",H21,IF(J21<>"",J21,D21))<>"",S21<>"",IF(H21<>"",H21,IF(J21<>"",J21,D21))>S21,K21="",L21=""),"Reason needed",IF(AND(G21="",OR(N(I21)>0,AND(C21<>"",C21<DATE(2024,6,30),X21=0))),"Start date needed",IF(AND(IF(H21<>"",H21,IF(J21<>"",J21,D21))<>"",IF(H21<>"",H21,IF(J21<>"",J21,D21))<DATE(2024,6,30)),"Finish date needed",IF(X21=1,"✓ Updated","Not changed yet"))))))) -> ✓ Complete | P21: Completed | R21: 45323 | S21: 45337 | T21: 45323 | U21: 45337 | X21: =IF(OR(G21<>T21,H21<>U21,I21<>V21,J21<>W21,K21<>"",L21<>""),1,0) -> 0 | Z21: 45337
A22: A1120 | B22: Design package 12 | C22: 45330 | D22: 45333 | E22: 1 | F22: 100 | G22: 45330 | H22: 45333 | M22: =IFERROR(IF(OR(D22="",IF(H22<>"",H22,IF(J22<>"",J22,D22))=""),"",IF(H22<>"",H22,IF(J22<>"",J22,D22))-D22),"") -> 0 | N22: =IFERROR(IF(OR(S22="",IF(H22<>"",H22,IF(J22<>"",J22,D22))=""),"",MAX(0,IF(H22<>"",H22,IF(J22<>"",J22,D22))-S22)),"") -> 0 | O22: =IF(OR(AND(G22<>"",NOT(ISNUMBER(G22))),AND(H22<>"",NOT(ISNUMBER(H22))),AND(J22<>"",NOT(ISNUMBER(J22)))),"Not a date",IF(OR(AND(G22<>"",N(G22)>TODAY()),AND(H22<>"",N(H22)>TODAY())),"Date in the future",IF(H22<>"",IF(G22="","Start date needed","✓ Complete"),IF(AND(IF(H22<>"",H22,IF(J22<>"",J22,D22))<>"",S22<>"",IF(H22<>"",H22,IF(J22<>"",J22,D22))>S22,K22="",L22=""),"Reason needed",IF(AND(G22="",OR(N(I22)>0,AND(C22<>"",C22<DATE(2024,6,30),X22=0))),"Start date needed",IF(AND(IF(H22<>"",H22,IF(J22<>"",J22,D22))<>"",IF(H22<>"",H22,IF(J22<>"",J22,D22))<DATE(2024,6,30)),"Finish date needed",IF(X22=1,"✓ Updated","Not changed yet"))))))) -> ✓ Complete | P22: Completed | R22: 45330 | S22: 45333 | T22: 45330 | U22: 45333 | X22: =IF(OR(G22<>T22,H22<>U22,I22<>V22,J22<>W22,K22<>"",L22<>""),1,0) -> 0 | Z22: 45333
... A29: A1190 | B29: Design package 19 | C29: 45352 | D29: 45359 | E29: 0 | F29: 100 | G29: 45352 | H29: 45359 | M29: =IFERROR(IF(OR(D29="",IF(H29<>"",H29,IF(J29<>"",J29,D29))=""),"",IF(H29<>"",H29,IF(J29<>"",J29,D29))-D29),"") -> 0 | N29: =IFERROR(IF(OR(S29="",IF(H29<>"",H29,IF(J29<>"",J29,D29))=""),"",MAX(0,IF(H29<>"",H29,IF(J29<>"",J29,D29))-S29)),"") -> 0 | O29: =IF(OR(AND(G29<>"",NOT(ISNUMBER(G29))),AND(H29<>"",NOT(ISNUMBER(H29))),AND(J29<>"",NOT(ISNUMBER(J29)))),"Not a date",IF(OR(AND(G29<>"",N(G29)>TODAY()),AND(H29<>"",N(H29)>TODAY())),"Date in the future",IF(H29<>"",IF(G29="","Start date needed","✓ Complete"),IF(AND(IF(H29<>"",H29,IF(J29<>"",J29,D29))<>"",S29<>"",IF(H29<>"",H29,IF(J29<>"",J29,D29))>S29,K29="",L29=""),"Reason needed",IF(AND(G29="",OR(N(I29)>0,AND(C29<>"",C29<DATE(2024,6,30),X29=0))),"Start date needed",IF(AND(IF(H29<>"",H29,IF(J29<>"",J29,D29))<>"",IF(H29<>"",H29,IF(J29<>"",J29,D29))<DATE(2024,6,30)),"Finish date needed",IF(X29=1,"✓ Updated","Not changed yet"))))))) -> ✓ Complete | P29: Completed | R29: 45352 | S29: 45359 | T29: 45352 | U29: 45359 | X29: =IF(OR(G29<>T29,H29<>U29,I29<>V29,J29<>W29,K29<>"",L29<>""),1,0) -> 0 | Z29: 45359

Sheet Priya Menon
A1: Programme update · Priya Menon - Project Manager
A2: SAMPLE-FITOUT · data date 30 Jun 2024 · Whole programme
A3: =IF(INFO("RECALC")="Automatic","","If these figures are struck through, or do not follow what is typed, Excel is calculating manually: press F9 to update them, or turn it on for good with Formulas › Calculation Options › Automatic.") -> If these figures are struck through, or do not follow what is typed, Excel is calculating manually: press F9 to update them, or turn it on for good with Formulas › Calculation Options › Automatic.
A4: 1 Type in the white columns only; grey is the programme, locked. Type dates like 14 Oct 2026. 2 Actual start / finish: dates that have happened - type over the programme's. Not finished yet? Leave Actual finish empty and give an Expected finish. 3 Finishing late? Give a delay cause or a note. Check says what is still needed. | C4: ACTIVITIES | E4: UPDATED | G4: NEED SOMETHING FROM YOU | J4: FINISHING LATE | L4: Grey: the programme | M4: =HYPERLINK("#Overview!C5","‹ Overview") -> ‹ Overview
C5: =COUNTA($P$10:$P$13) -> 2 | E5: =SUM($X$10:$X$13) -> 0 | G5: =COUNTIF($O$10:$O$13,"Reason needed")+COUNTIF($O$10:$O$13,"Start date needed")+COUNTIF($O$10:$O$13,"Finish date needed")+COUNTIF($O$10:$O$13,"Date in the future") -> 0 | J5: =COUNTIFS($N$10:$N$13,">0",$H$10:$H$13,"") -> 0 | L5: White: your update | M5: Red in Check: still needed
C6: ="in this update" -> in this update | E6: =IFERROR(TEXT(SUM($X$10:$X$13)/COUNTA($P$10:$P$13),"0%"),"0%")&" done" -> 0% done | G6: ="red in the Check column" -> red in the Check column | J6: ="not finished, past the planned finish" -> not finished, past the planned finish | L6: Green: you changed it | M6: Bold red ID: critical
A8: THE PROGRAMME (locked) | G8: YOUR UPDATE | M8: CHECK
A9: Activity ID | B9: Activity name | C9: Start | D9: Finish | E9: Float (d) | F9: Physical % complete | G9: Actual start | H9: Actual finish | I9: Actual % complete | J9: Expected finish | K9: Delay cause | L9: Notes | M9: Finish moves (d) | N9: Days late | O9: Check | P9: Status | Q9: Critical | R9: Planned start | S9: Compare finish | T9: was actual start | U9: was actual finish | V9: was actual % | W9: was expected finish | X9: changed | Y9: WBS level | Z9: Planned finish
A10: ENG Engineering | Y10: 1
A11: A1000 | B11: Design package 00 | C11: 45293 | D11: 45300 | E11: 0 | F11: 100 | G11: 45293 | H11: 45300 | M11: =IFERROR(IF(OR(D11="",IF(H11<>"",H11,IF(J11<>"",J11,D11))=""),"",IF(H11<>"",H11,IF(J11<>"",J11,D11))-D11),"") -> 0 | N11: =IFERROR(IF(OR(S11="",IF(H11<>"",H11,IF(J11<>"",J11,D11))=""),"",MAX(0,IF(H11<>"",H11,IF(J11<>"",J11,D11))-S11)),"") -> 0 | O11: =IF(OR(AND(G11<>"",NOT(ISNUMBER(G11))),AND(H11<>"",NOT(ISNUMBER(H11))),AND(J11<>"",NOT(ISNUMBER(J11)))),"Not a date",IF(OR(AND(G11<>"",N(G11)>TODAY()),AND(H11<>"",N(H11)>TODAY())),"Date in the future",IF(H11<>"",IF(G11="","Start date needed","✓ Complete"),IF(AND(IF(H11<>"",H11,IF(J11<>"",J11,D11))<>"",S11<>"",IF(H11<>"",H11,IF(J11<>"",J11,D11))>S11,K11="",L11=""),"Reason needed",IF(AND(G11="",OR(N(I11)>0,AND(C11<>"",C11<DATE(2024,6,30),X11=0))),"Start date needed",IF(AND(IF(H11<>"",H11,IF(J11<>"",J11,D11))<>"",IF(H11<>"",H11,IF(J11<>"",J11,D11))<DATE(2024,6,30)),"Finish date needed",IF(X11=1,"✓ Updated","Not changed yet"))))))) -> ✓ Complete | P11: Completed | R11: 45293 | S11: 45300 | T11: 45293 | U11: 45300 | X11: =IF(OR(G11<>T11,H11<>U11,I11<>V11,J11<>W11,K11<>"",L11<>""),1,0) -> 0 | Z11: 45300
A12: CON Construction | Y12: 1
A13: A1590 | B13: Build package 59 | C13: 45660 | D13: 45681 | E13: 50 | F13: 0 | M13: =IFERROR(IF(OR(D13="",IF(H13<>"",H13,IF(J13<>"",J13,D13))=""),"",IF(H13<>"",H13,IF(J13<>"",J13,D13))-D13),"") -> 0 | N13: =IFERROR(IF(OR(S13="",IF(H13<>"",H13,IF(J13<>"",J13,D13))=""),"",MAX(0,IF(H13<>"",H13,IF(J13<>"",J13,D13))-S13)),"") -> 0 | O13: =IF(OR(AND(G13<>"",NOT(ISNUMBER(G13))),AND(H13<>"",NOT(ISNUMBER(H13))),AND(J13<>"",NOT(ISNUMBER(J13)))),"Not a date",IF(OR(AND(G13<>"",N(G13)>TODAY()),AND(H13<>"",N(H13)>TODAY())),"Date in the future",IF(H13<>"",IF(G13="","Start date needed","✓ Complete"),IF(AND(IF(H13<>"",H13,IF(J13<>"",J13,D13))<>"",S13<>"",IF(H13<>"",H13,IF(J13<>"",J13,D13))>S13,K13="",L13=""),"Reason needed",IF(AND(G13="",OR(N(I13)>0,AND(C13<>"",C13<DATE(2024,6,30),X13=0))),"Start date needed",IF(AND(IF(H13<>"",H13,IF(J13<>"",J13,D13))<>"",IF(H13<>"",H13,IF(J13<>"",J13,D13))<DATE(2024,6,30)),"Finish date needed",IF(X13=1,"✓ Updated","Not changed yet"))))))) -> Not changed yet | P13: Not Started | R13: 45660 | S13: 45681 | X13: =IF(OR(G13<>T13,H13<>U13,I13<>V13,J13<>W13,K13<>"",L13<>""),1,0) -> 0 | Z13: 45681

Sheet Sara Moss
A1: Programme update · Sara Moss - Site Manager
A2: SAMPLE-FITOUT · data date 30 Jun 2024 · Whole programme
A3: =IF(INFO("RECALC")="Automatic","","If these figures are struck through, or do not follow what is typed, Excel is calculating manually: press F9 to update them, or turn it on for good with Formulas › Calculation Options › Automatic.") -> If these figures are struck through, or do not follow what is typed, Excel is calculating manually: press F9 to update them, or turn it on for good with Formulas › Calculation Options › Automatic.
A4: 1 Type in the white columns only; grey is the programme, locked. Type dates like 14 Oct 2026. 2 Actual start / finish: dates that have happened - type over the programme's. Not finished yet? Leave Actual finish empty and give an Expected finish. 3 Finishing late? Give a delay cause or a note. Check says what is still needed. | C4: ACTIVITIES | E4: UPDATED | G4: NEED SOMETHING FROM YOU | J4: FINISHING LATE | L4: Grey: the programme | M4: =HYPERLINK("#Overview!C5","‹ Overview") -> ‹ Overview
C5: =COUNTA($P$10:$P$30) -> 20 | E5: =SUM($X$10:$X$30) -> 0 | G5: =COUNTIF($O$10:$O$30,"Reason needed")+COUNTIF($O$10:$O$30,"Start date needed")+COUNTIF($O$10:$O$30,"Finish date needed")+COUNTIF($O$10:$O$30,"Date in the future") -> 2 | J5: =COUNTIFS($N$10:$N$30,">0",$H$10:$H$30,"") -> 0 | L5: White: your update | M5: Red in Check: still needed
C6: ="in this update" -> in this update | E6: =IFERROR(TEXT(SUM($X$10:$X$30)/COUNTA($P$10:$P$30),"0%"),"0%")&" done" -> 0% done | G6: ="red in the Check column" -> red in the Check column | J6: ="not finished, past the planned finish" -> not finished, past the planned finish | L6: Green: you changed it | M6: Bold red ID: critical
A8: THE PROGRAMME (locked) | G8: YOUR UPDATE | M8: CHECK
A9: Activity ID | B9: Activity name | C9: Start | D9: Finish | E9: Float (d) | F9: Physical % complete | G9: Actual start | H9: Actual finish | I9: Actual % complete | J9: Expected finish | K9: Delay cause | L9: Notes | M9: Finish moves (d) | N9: Days late | O9: Check | P9: Status | Q9: Critical | R9: Planned start | S9: Compare finish | T9: was actual start | U9: was actual finish | V9: was actual % | W9: was expected finish | X9: changed | Y9: WBS level | Z9: Planned finish
A10: CON Construction | Y10: 1
